>>> call foo ()
wrong-calls.hlt:9: error, function returns a value


1 error found
