>>> call foo ()
wrong-calls.hlt:9: error, called function returns a value

wrong-calls.hlt: 1 error found during validating
