>>> call foo (42, 43)
wrong-calls.hlt:7: error, wrong number of arguments for function


1 error found
